Workbook

Sheet summary_dashboard
A1: Travidz — Financial Model v1 (60 months)
A2: Scenario: | B2: Base | C2: (Base / Bear / Bull)
A4: KEY METRICS
A5: Metric | B5: M12 (Y1) | C5: M24 (Y2) | D5: M36 (Y3) | E5: M48 (Y4) | F5: M60 (Y5)
A6: Active creators (EOY) | B6: =creator_cohorts!M5 -> 500 | C6: =creator_cohorts!Y5 -> 2400 | D6: =creator_cohorts!AK5 -> 6800 | E6: =creator_cohorts!AW5 -> 14000 | F6: =creator_cohorts!BI5 -> 24000
A7: Active operators (EOY) | B7: =operator_supply!M5 -> 155 | C7: =operator_supply!Y5 -> 273 | D7: =operator_supply!AK5 -> 378 | E7: =operator_supply!AW5 -> 471 | F7: =operator_supply!BI5 -> 555
A8: Active FTE (EOY) | B8: =headcount_uk!R45 -> 16 | C8: =headcount_uk!AD45 -> 21 | D8: =headcount_uk!AP45 -> 27 | E8: =headcount_uk!BB45 -> 33 | F8: =headcount_uk!BN45 -> 39
A9: Annual GBV | B9: =SUM(creator_cohorts!B11:M11) -> 2708272.7 | C9: =SUM(creator_cohorts!N11:Y11) -> 20715300 | D9: =SUM(creator_cohorts!Z11:AK11) -> 74199150 | E9: =SUM(creator_cohorts!AL11:AW11) -> 181010000 | F9: =SUM(creator_cohorts!AX11:BI11) -> 350102510
A10: Annual Travidz net revenue | B10: =SUM(creator_cohorts!B22:M22) -> 108330.91 | C10: =SUM(creator_cohorts!N22:Y22) -> 844950.99 | D10: =SUM(creator_cohorts!Z22:AK22) -> 3187210.4 | E10: =SUM(creator_cohorts!AL22:AW22) -> 8182738.9 | F10: =SUM(creator_cohorts!AX22:BI22) -> 16220220
A11: Blended take-rate | B11: =SUM(creator_cohorts!B22:M22)/SUM(creator_cohorts!B11:M11) -> 0.04 | C11: =SUM(creator_cohorts!N22:Y22)/SUM(creator_cohorts!N11:Y11) -> 0.04078874 | D11: =SUM(creator_cohorts!Z22:AK22)/SUM(creator_cohorts!Z11:AK11) -> 0.04295481 | E11: =SUM(creator_cohorts!AL22:AW22)/SUM(creator_cohorts!AL11:AW11) -> 0.045206005 | F11: =SUM(creator_cohorts!AX22:BI22)/SUM(creator_cohorts!AX11:BI11) -> 0.046329916
A12: Annual EBITDA | B12: =SUM(combined_pnl_cash!B31:M31) -> -1555576.9 | C12: =SUM(combined_pnl_cash!N31:Y31) -> -2407347.9 | D12: =SUM(combined_pnl_cash!Z31:AK31) -> -2487924.5 | E12: =SUM(combined_pnl_cash!AL31:AW31) -> -1372015.4 | F12: =SUM(combined_pnl_cash!AX31:BI31) -> 2859627.5
A13: EBITDA margin | B13: =SUM(combined_pnl_cash!B31:M31)/SUM(creator_cohorts!B22:M22) -> -14.359492 | C13: =SUM(combined_pnl_cash!N31:Y31)/SUM(creator_cohorts!N22:Y22) -> -2.8490976 | D13: =SUM(combined_pnl_cash!Z31:AK31)/SUM(creator_cohorts!Z22:AK22) -> -0.78059626 | E13: =SUM(combined_pnl_cash!AL31:AW31)/SUM(creator_cohorts!AL22:AW22) -> -0.1676719 | F13: =SUM(combined_pnl_cash!AX31:BI31)/SUM(creator_cohorts!AX22:BI22) -> 0.17630017
A14: Closing cash (EOY) | B14: =combined_pnl_cash!M39 -> 994423.14 | C14: =combined_pnl_cash!Y39 -> 6587075.3 | D14: =combined_pnl_cash!AK39 -> 4099150.8 | E14: =combined_pnl_cash!AW39 -> 22727135 | F14: =combined_pnl_cash!BI39 -> 25586763
A15: Peak cash deficit | B15: =combined_pnl_cash!M40 -> 994423.14 | C15: =combined_pnl_cash!Y40 -> -813490.44 | D15: =combined_pnl_cash!AK40 -> -813490.44 | E15: =combined_pnl_cash!AW40 -> -813490.44 | F15: =combined_pnl_cash!BI40 -> -813490.44
A17: SUMMARY KPIs
A18: Peak monthly burn (£) | B18: =-MIN(combined_pnl_cash!B31:BI31) -> 266576.25
A19: Month of peak burn | B19: ="M"&MATCH(MIN(combined_pnl_cash!B31:BI31),combined_pnl_cash!B31:BI31,0) -> M26
A20: Months to EBITDA breakeven | B20: =IFERROR(MATCH(TRUE(),INDEX(combined_pnl_cash!B31:BI31>0,0),0),"not in 60mo") -> 48
A21: Peak cash deficit (£) | B21: =MIN(combined_pnl_cash!B40:BI40) -> -813490.44
A22: Required seed (peak burn × -1 + 25% buffer) | B22: =-MIN(combined_pnl_cash!B40:BI40)*1.25-assumptions!$G$125-assumptions!$G$127 -> -26983137
A23: Y5 ARR-equivalent (Travidz net × 12 at M60) | B23: =combined_pnl_cash!BI5*12 -> 20650291
A24: Y5 Annual GBV | B24: =SUM(creator_cohorts!AX11:BI11) -> 350102510
A25: Y5 Travidz net revenue | B25: =SUM(creator_cohorts!AX22:BI22) -> 16220220
A26: Y5 Active creators | B26: =creator_cohorts!BI5 -> 24000
A27: Y5 Active FTE | B27: =headcount_uk!BN45 -> 39
A28: Y5 Blended take-rate | B28: =SUM(creator_cohorts!AX22:BI22)/SUM(creator_cohorts!AX11:BI11) -> 0.046329916
A31: v6 TS-MODEL CROSS-CHECK (target — should match Base)
A32: Metric | B32: Target (v6) | C32: Model Y5 | D32: Delta
A33: Y5 Active creators | B33: 24000 | C33: =creator_cohorts!BI5 -> 24000 | D33: =C33-B33 -> 0
A34: Y5 Annual GBV | B34: 444000000 | C34: =SUM(creator_cohorts!AX11:BI11) -> 350102510 | D34: =C34-B34 -> -93897490
A35: Y5 Travidz net | B35: 20672640 | C35: =SUM(creator_cohorts!AX22:BI22) -> 16220220 | D35: =C35-B35 -> -4452420.2
A36: Y5 Take-rate | B36: 0.04656 | C36: =SUM(creator_cohorts!AX22:BI22)/SUM(creator_cohorts!AX11:BI11) -> 0.046329916 | D36: =C36-B36 -> -0.00023008413
A39: Charts inserted to the right →

Sheet global_viral_summary
A1: Travidz — Global Viral Scenario (Y1–Y5)
A2: Pre-launch model. UK Base remains the funded plan. Global Viral assumes one breakout region per year (US, AUS/NZ, LATAM, MENA, SEA, India) and a TikTok-style creator loop.
A4: Metric | B4: Y1 | C4: Y2 | D4: Y3 | E4: Y4 | F4: Y5 | G4: vs UK Base Y5
A5: Active creators (EOY) | B5: 1500 | C5: 9000 | D5: 32000 | E5: 70000 | F5: 120000 | G5: 5.0x
A6: Annual GBV (£) | B6: 4050000 | C6: 59850000 | D6: 255840000 | E6: 679320000 | F6: 1322400000 | G6: 3.8x
A7: Gross commission (£) | B7: 324000 | C7: 4788000 | D7: 20467200 | E7: 54345600 | F7: 105792000 | G7: 3.8x
A8: Creator payout (£) | B8: 162000 | C8: 2322180 | D8: 9210240 | E8: 23096880 | F8: 44221056
A9: Travidz net revenue (£) | B9: 162000 | C9: 2465820 | D9: 11256960 | E9: 31248720 | F9: 61570944 | G9: 3.8x
A10: Blended take-rate | B10: 0.04 | C10: 0.0412 | D10: 0.044 | E10: 0.046 | F10: 0.04656 | G10: 1.0x
A13: Y5 SIDE-BY-SIDE
A14: Metric | B14: UK Base | C14: Global Viral | D14: Multiplier
A15: Active creators | B15: 24000 | C15: 120000 | D15: 5.0x
A16: Annual GBV (£) | B16: 350102510 | C16: 1322400000 | D16: 3.8x
A17: Travidz net revenue (£) | B17: 16220220 | C17: 61570944 | D17: 3.8x
A18: Blended take-rate | B18: 0.04633 | C18: 0.04656 | D18: 1.0x

Sheet regions
A1: Travidz — Regional Build (Y5, Global Viral)
A2: Bottom-up Y5 split across launch regions. Sum of creators and GBV ties back to global_viral_summary Y5.
A4: Region | B4: Reachable travellers (M) | C4: Active creators @ Y5 | D4: ABV (£) | E4: Annual GBV (£) | F4: Travidz net (£)
A5: United Kingdom | B5: 25 | C5: 6000 | D5: 480 | E5: 84558437 | F5: 3937040.8
A6: EU-5 (FR/DE/ES/IT/NL) | B6: 150 | C6: 14000 | D6: 460 | E6: 1.8908206e+08 | F6: 8803660.7
A7: USA | B7: 180 | C7: 22000 | D7: 540 | E7: 3.4880355e+08 | F7: 16240293
A8: Australia / NZ | B8: 18 | C8: 6000 | D8: 580 | E8: 1.0217478e+08 | F8: 4757257.7
A9: LATAM (Brazil-led) | B9: 110 | C9: 14000 | D9: 280 | E9: 1.1509343e+08 | F9: 5358750
A10: MENA | B10: 70 | C10: 8000 | D10: 380 | E10: 89256128 | F10: 4155765.3
A11: Africa | B11: 90 | C11: 6000 | D11: 220 | E11: 38755950 | F11: 1804477
A12: India | B12: 140 | C12: 16000 | D12: 200 | E12: 93953819 | F12: 4374489.8
A13: SEA | B13: 160 | C13: 16000 | D13: 240 | E13: 1.1274458e+08 | F13: 5249387.8
A14: Greater China | B14: 280 | C14: 12000 | D14: 420 | E14: 1.4797726e+08 | F14: 6889821.4
A15: TOTAL | B15: 1223 | C15: 120000 | E15: 1322400000 | F15: 61570944

Sheet assumptions
A1: Travidz — Assumptions (60 months)
A2: Blue = input. Edit Base / Bear / Bull. Active column drives all sheets via scenario_idx on summary_dashboard.
A3: Parameter | B3: Base | C3: Bear | D3: Bull | E3: Global Viral | F3: Notes | G3: Active | H3: Default note
A4: MARKET & COMMISSION (v6 base case)
A5: TAM travellers (#) | B5: 85000000 | C5: 70000000 | D5: 95000000 | E5: 520000000 | F5: Reachable UK + key EU traveller pool | G5: =CHOOSE(scenario_idx,B5,C5,D5,E5) -> 85000000
A6: Average booking value (£) | B6: 480 | C6: 420 | D6: 540 | E6: 410 | F6: Avg per booking | G6: =CHOOSE(scenario_idx,B6,C6,D6,E6) -> 480
A7: Bookings per traveller / yr | B7: 1.6 | C7: 1.4 | D7: 1.8 | E7: 1.5 | F7: Attach rate | G7: =CHOOSE(scenario_idx,B7,C7,D7,E7) -> 1.6
A8: SAM % of TAM | B8: 0.28 | C8: 0.22 | D8: 0.35 | E8: 0.26 | F8: Creator-led discoverable inventory | G8: =CHOOSE(scenario_idx,B8,C8,D8,E8) -> 0.28
A9: Gross commission % | B9: 0.08 | C9: 0.08 | D9: 0.08 | E9: 0.08 | F9: 8% headline to operators | G9: =CHOOSE(scenario_idx,B9,C9,D9,E9) -> 0.08
A10: Creator share — Founding | B10: 0.5 | C10: 0.5 | D10: 0.5 | E10: 0.5 | F10: First 500, lifetime | G10: =CHOOSE(scenario_idx,B10,C10,D10,E10) -> 0.5
A11: Creator share — Power | B11: 0.5 | C11: 0.5 | D11: 0.5 | E11: 0.5 | F11: >£25k rolling 12mo | G11: =CHOOSE(scenario_idx,B11,C11,D11,E11) -> 0.5
A12: Creator share — New (0–6mo) | B12: 0.5 | C12: 0.5 | D12: 0.5 | E12: 0.5 | G12: =CHOOSE(scenario_idx,B12,C12,D12,E12) -> 0.5
A13: Creator share — Maturing (7–18mo) | B13: 0.4 | C13: 0.4 | D13: 0.4 | E13: 0.4 | G13: =CHOOSE(scenario_idx,B13,C13,D13,E13) -> 0.4
A14: Creator share — Mature (19mo+) | B14: 0.3 | C14: 0.3 | D14: 0.3 | E14: 0.3 | G14: =CHOOSE(scenario_idx,B14,C14,D14,E14) -> 0.3
A15: CREATOR FUNNEL — Active creators (year-end anchors)
A16: Active creators @ M0 | B16: 0 | C16: 0 | D16: 0 | E16: 0 | G16: =CHOOSE(scenario_idx,B16,C16,D16,E16) -> 0
A17: Active creators @ M12 | B17: 500 | C17: 350 | D17: 700 | E17: 1500 | F17: v6 Y1 | G17: =CHOOSE(scenario_idx,B17,C17,D17,E17) -> 500
A18: Active creators @ M24 | B18: 2400 | C18: 1500 | D18: 3500 | E18: 9000 | F18: v6 Y2 | G18: =CHOOSE(scenario_idx,B18,C18,D18,E18) -> 2400
A19: Active creators @ M36 | B19: 6800 | C19: 4200 | D19: 9500 | E19: 32000 | F19: v6 Y3 | G19: =CHOOSE(scenario_idx,B19,C19,D19,E19) -> 6800
A20: Active creators @ M48 | B20: 14000 | C20: 9000 | D20: 19000 | E20: 70000 | F20: v6 Y4 | G20: =CHOOSE(scenario_idx,B20,C20,D20,E20) -> 14000
A21: Active creators @ M60 | B21: 24000 | C21: 16000 | D21: 32000 | E21: 120000 | F21: v6 Y5 | G21: =CHOOSE(scenario_idx,B21,C21,D21,E21) -> 24000
A22: Monthly creator churn % | B22: 0.02 | C22: 0.035 | D22: 0.012 | E22: 0.018 | F22: Logo churn | G22: =CHOOSE(scenario_idx,B22,C22,D22,E22) -> 0.02
A23: CREATOR GBV/active (monthly £, year-end anchors)
A24: GBV/active/mo @ M12 (£) | B24: 1000 | C24: 850 | D24: 1150 | E24: 900 | F24: Ramp anchor | G24: =CHOOSE(scenario_idx,B24,C24,D24,E24) -> 1000
A25: GBV/active/mo @ M24 (£) | B25: 1200 | C25: 1000 | D25: 1350 | E25: 1000 | G25: =CHOOSE(scenario_idx,B25,C25,D25,E25) -> 1200
A26: GBV/active/mo @ M36 (£) | B26: 1350 | C26: 1100 | D26: 1500 | E26: 1080 | G26: =CHOOSE(scenario_idx,B26,C26,D26,E26) -> 1350
A27: GBV/active/mo @ M48 (£) | B27: 1450 | C27: 1180 | D27: 1620 | E27: 1140 | G27: =CHOOSE(scenario_idx,B27,C27,D27,E27) -> 1450
A28: GBV/active/mo @ M60 (£) | B28: 1540 | C28: 1250 | D28: 1700 | E28: 1180 | F28: v6 implied £18.5k/yr | G28: =CHOOSE(scenario_idx,B28,C28,D28,E28) -> 1540
A29: CREATOR TIER MIX (year-end shares)
A30: Mix — Founding Y1 | B30: 1 | C30: 1 | D30: 1 | E30: 1 | G30: =CHOOSE(scenario_idx,B30,C30,D30,E30) -> 1
A31: Mix — Founding Y2 | B31: 0.45 | C31: 0.45 | D31: 0.45 | E31: 0.45 | G31: =CHOOSE(scenario_idx,B31,C31,D31,E31) -> 0.45
A32: Mix — Founding Y3 | B32: 0.22 | C32: 0.22 | D32: 0.22 | E32: 0.22 | G32: =CHOOSE(scenario_idx,B32,C32,D32,E32) -> 0.22
A33: Mix — Founding Y4 | B33: 0.12 | C33: 0.12 | D33: 0.12 | E33: 0.12 | G33: =CHOOSE(scenario_idx,B33,C33,D33,E33) -> 0.12
A34: Mix — Founding Y5 | B34: 0.08 | C34: 0.08 | D34: 0.08 | E34: 0.08 | G34: =CHOOSE(scenario_idx,B34,C34,D34,E34) -> 0.08
A35: Mix — Power Y1 | B35: 0 | C35: 0 | D35: 0 | E35: 0 | G35: =CHOOSE(scenario_idx,B35,C35,D35,E35) -> 0
A36: Mix — Power Y2 | B36: 0.05 | C36: 0.05 | D36: 0.05 | E36: 0.05 | G36: =CHOOSE(scenario_idx,B36,C36,D36,E36) -> 0.05
A37: Mix — Power Y3 | B37: 0.18 | C37: 0.18 | D37: 0.18 | E37: 0.18 | G37: =CHOOSE(scenario_idx,B37,C37,D37,E37) -> 0.18
A38: Mix — Power Y4 | B38: 0.28 | C38: 0.28 | D38: 0.28 | E38: 0.28 | G38: =CHOOSE(scenario_idx,B38,C38,D38,E38) -> 0.28
A39: Mix — Power Y5 | B39: 0.34 | C39: 0.34 | D39: 0.34 | E39: 0.34 | G39: =CHOOSE(scenario_idx,B39,C39,D39,E39) -> 0.34
A40: Mix — New Y1 | B40: 0 | C40: 0 | D40: 0 | E40: 0 | G40: =CHOOSE(scenario_idx,B40,C40,D40,E40) -> 0
...

Sheet channel_cac
A1: Channel CAC — Creator & Operator acquisition
A3: Channel split shown for CAC discipline. Monthly £ totals on assumptions drive cash.
A5: CREATOR ACQUISITION
A6: Channel | B6: Spend share | C6: CPL £ | D6: Conv % | E6: CAC £ | F6: New creators/mo @ M12 | G6: CAC @ M36 | H6: New /mo @ M36
A7: Paid Social (TikTok/IG) | B7: 0.4 | C7: 8 | D7: 0.06 | E7: =IF(D7>0,C7/D7,0) -> 133.33333 | F7: =IFERROR(assumptions!$G$116*B7/E7,0) -> 60 | G7: =E7*1.1 -> 146.66667 | H7: =IFERROR(assumptions!$G$118*B7/G7,0) -> 163.63636
A8: Creator Referral | B8: 0.2 | C8: 3 | D8: 0.18 | E8: =IF(D8>0,C8/D8,0) -> 16.666667 | F8: =IFERROR(assumptions!$G$116*B8/E8,0) -> 240 | G8: =E8*1.1 -> 18.333333 | H8: =IFERROR(assumptions!$G$118*B8/G8,0) -> 654.54545
A9: Founding-500 Programme | B9: 0.15 | C9: 0 | D9: 0 | E9: 200 | F9: =IFERROR(assumptions!$G$116*B9/E9,0) -> 15 | G9: =E9*1.1 -> 220 | H9: =IFERROR(assumptions!$G$118*B9/G9,0) -> 40.909091
A10: SEO / Content | B10: 0.1 | C10: 4 | D10: 0.05 | E10: =IF(D10>0,C10/D10,0) -> 80 | F10: =IFERROR(assumptions!$G$116*B10/E10,0) -> 25 | G10: =E10*1.1 -> 88 | H10: =IFERROR(assumptions!$G$118*B10/G10,0) -> 68.181818
A11: Events / meetups | B11: 0.1 | C11: 25 | D11: 0.1 | E11: =IF(D11>0,C11/D11,0) -> 250 | F11: =IFERROR(assumptions!$G$116*B11/E11,0) -> 8 | G11: =E11*1.1 -> 275 | H11: =IFERROR(assumptions!$G$118*B11/G11,0) -> 21.818182
A12: Direct outreach | B12: 0.05 | C12: 12 | D12: 0.08 | E12: =IF(D12>0,C12/D12,0) -> 150 | F12: =IFERROR(assumptions!$G$116*B12/E12,0) -> 6.6666667 | G12: =E12*1.1 -> 165 | H12: =IFERROR(assumptions!$G$118*B12/G12,0) -> 18.181818
A13: Total | B13: =SUM(B7:B12) -> 1 | E13: =SUMPRODUCT(B7:B12,E7:E12) -> 127.16667 | F13: =SUM(F7:F12) -> 354.66667 | G13: =SUMPRODUCT(B7:B12,G7:G12) -> 139.88333 | H13: =SUM(H7:H12) -> 967.27273
A16: OPERATOR ACQUISITION
A17: Channel | B17: Spend share | C17: CPL £ | D17: Conv % | E17: CAC £ | F17: New ops/mo @ M12 | G17: CAC @ M36 | H17: New ops/mo @ M36
A18: Outbound sales | B18: 0.55 | C18: 0 | D18: 0 | E18: 400 | F18: =IFERROR(assumptions!$G$120*B18/E18,0) -> 6.875 | G18: =E18*1.1 -> 440 | H18: =IFERROR(assumptions!$G$120*B18/G18,0) -> 6.25
A19: Inbound demo | B19: 0.2 | C19: 20 | D19: 0.25 | E19: =IF(D19>0,C19/D19,0) -> 80 | F19: =IFERROR(assumptions!$G$120*B19/E19,0) -> 12.5 | G19: =E19*1.1 -> 88 | H19: =IFERROR(assumptions!$G$120*B19/G19,0) -> 11.363636
A20: Partner referral | B20: 0.15 | C20: 10 | D20: 0.4 | E20: =IF(D20>0,C20/D20,0) -> 25 | F20: =IFERROR(assumptions!$G$120*B20/E20,0) -> 30 | G20: =E20*1.1 -> 27.5 | H20: =IFERROR(assumptions!$G$120*B20/G20,0) -> 27.272727
A21: Events/trade show | B21: 0.1 | C21: 50 | D21: 0.15 | E21: =IF(D21>0,C21/D21,0) -> 333.33333 | F21: =IFERROR(assumptions!$G$120*B21/E21,0) -> 1.5 | G21: =E21*1.1 -> 366.66667 | H21: =IFERROR(assumptions!$G$120*B21/G21,0) -> 1.3636364
A22: Total | E22: =SUMPRODUCT(B18:B21,E18:E21) -> 273.08333 | F22: =SUM(F18:F21) -> 50.875

Sheet headcount_uk
A1: UK Headcount Plan (60 months) — loaded cost incl. NIC, pension, benefits, recruitment
A3: # | B3: Role | C3: Team | D3: Base £/yr | E3: Start M | F3: End M | G3: M1 | H3: M2 | I3: M3 | J3: M4 | K3: M5 | L3: M6 | M3: M7 | N3: M8 | O3: M9 | P3: M10 | Q3: M11 | R3: M12 | S3: M13 | T3: M14 | U3: M15 | V3: M16 | W3: M17 | X3: M18 | Y3: M19 | Z3: M20 | AA3: M21 | AB3: M22 | AC3: M23 | AD3: M24 | AE3: M25 | AF3: M26 | AG3: M27 | AH3: M28 | AI3: M29 | AJ3: M30 | AK3: M31 | AL3: M32 | AM3: M33 | AN3: M34 | AO3: M35 | AP3: M36 | AQ3: M37 | AR3: M38 | AS3: M39 | AT3: M40 | AU3: M41 | AV3: M42 | AW3: M43 | AX3: M44 | AY3: M45 | AZ3: M46 | BA3: M47 | BB3: M48 | BC3: M49 | BD3: M50 | BE3: M51 | BF3: M52 | BG3: M53 | BH3: M54 | BI3: M55 | BJ3: M56 | BK3: M57 | BL3: M58 | BM3: M59 | BN3: M60
A4: 1 | B4: CEO / Founder | C4: exec | D4: 85000 | E4: 1 | G4: =IF(AND(1>=E4,OR(F4="",1<=F4)),(D4*(1+assumptions!$G$76)^0/12*(1+assumptions!$G$70+assumptions!$G$71+IF(1>=assumptions!$G$73,assumptions!$G$72,0))+assumptions!$G$74/12)+IF(1=E4,D4*assumptions!$G$75,0),0) -> 21323.333 | H4: =IF(AND(2>=E4,OR(F4="",2<=F4)),(D4*(1+assumptions!$G$76)^0/12*(1+assumptions!$G$70+assumptions!$G$71+IF(2>=assumptions!$G$73,assumptions!$G$72,0))+assumptions!$G$74/12)+IF(2=E4,D4*assumptions!$G$75,0),0) -> 8573.3333 | I4: =IF(AND(3>=E4,OR(F4="",3<=F4)),(D4*(1+assumptions!$G$76)^0/12*(1+assumptions!$G$70+assumptions!$G$71+IF(3>=assumptions!$G$73,assumptions!$G$72,0))+assumptions!$G$74/12)+IF(3=E4,D4*assumptions!$G$75,0),0) -> 8573.3333 | J4: =IF(AND(4>=E4,OR(F4="",4<=F4)),(D4*(1+assumptions!$G$76)^0/12*(1+assumptions!$G$70+assumptions!$G$71+IF(4>=assumptions!$G$73,assumptions!$G$72,0))+assumptions!$G$74/12)+IF(4=E4,D4*assumptions!$G$75,0),0) -> 8573.3333 | K4: =IF(AND(5>=E4,OR(F4="",5<=F4)),(D4*(1+assumptions!$G$76)^0/12*(1+assumptions!$G$70+assumptions!$G$71+IF(5>=assumptions!$G$73,assumptions!$G$72,0))+assumptions!$G$74/12)+IF(5=E4,D4*assumptions!$G$75,0),0) -> 8573.3333 | L4: =IF(AND(6>=E4,OR(F4="",6<=F4)),(D4*(1+assumptions!$G$76)^0/12*(1+assumptions!$G$70+assumptions!$G$71+IF(6>=assumptions!$G$73,assumptions!$G$72,0))+assumptions!$G$74/12)+IF(6=E4,D4*assumptions!$G$75,0),0) -> 8573.3333 | M4: =IF(AND(7>=E4,OR(F4="",7<=F4)),(D4*(1+assumptions!$G$76)^0/12*(1+assumptions!$G$70+assumptions!$G$71+IF(7>=assumptions!$G$73,assumptions!$G$72,0))+assumptions!$G$74/12)+IF(7=E4,D4*assumptions!$G$75,0),0) -> 8573.3333 | N4: =IF(AND(8>=E4,OR(F4="",8<=F4)),(D4*(1+assumptions!$G$76)^0/12*(1+assumptions!$G$70+assumptions!$G$71+IF(8>=assumptions!$G$73,assumptions!$G$72,0))+assumptions!$G$74/12)+IF(8=E4,D4*assumptions!$G$75,0),0) -> 8573.3333 | O4: =IF(AND(9>=E4,OR(F4="",9<=F4)),(D4*(1+assumptions!$G$76)^0/12*(1+assumptions!$G$70+assumptions!$G$71+IF(9>=assumptions!$G$73,assumptions!$G$72,0))+assumptions!$G$74/12)+IF(9=E4,D4*assumptions!$G$75,0),0) -> 8573.3333 | P4: =IF(AND(10>=E4,OR(F4="",10<=F4)),(D4*(1+assumptions!$G$76)^0/12*(1+assumptions!$G$70+assumptions!$G$71+IF(10>=assumptions!$G$73,assumptions!$G$72,0))+assumptions!$G$74/12)+IF(10=E4,D4*assumptions!$G$75,0),0) -> 8573.3333 | Q4: =IF(AND(11>=E4,OR(F4="",11<=F4)),(D4*(1+assumptions!$G$76)^0/12*(1+assumptions!$G$70+assumptions!$G$71+IF(11>=assumptions!$G$73,assumptions!$G$72,0))+assumptions!$G$74/12)+IF(11=E4,D4*assumptions!$G$75,0),0) -> 8573.3333 | R4: =IF(AND(12>=E4,OR(F4="",12<=F4)),(D4*(1+assumptions!$G$76)^0/12*(1+assumptions!$G$70+assumptions!$G$71+IF(12>=assumptions!$G$73,assumptions!$G$72,0))+assumptions!$G$74/12)+IF(12=E4,D4*assumptions!$G$75,0),0) -> 8573.3333 | S4: =IF(AND(13>=E4,OR(F4="",13<=F4)),(D4*(1+assumptions!$G$76)^1/12*(1+assumptions!$G$70+assumptions!$G$71+IF(13>=assumptions!$G$73,assumptions!$G$72,0))+assumptions!$G$74/12)+IF(13=E4,D4*assumptions!$G$75,0),0) -> 8904.2667 | T4: =IF(AND(14>=E4,OR(F4="",14<=F4)),(D4*(1+assumptions!$G$76)^1/12*(1+assumptions!$G$70+assumptions!$G$71+IF(14>=assumptions!$G$73,assumptions!$G$72,0))+assumptions!$G$74/12)+IF(14=E4,D4*assumptions!$G$75,0),0) -> 8904.2667 | U4: =IF(AND(15>=E4,OR(F4="",15<=F4)),(D4*(1+assumptions!$G$76)^1/12*(1+assumptions!$G$70+assumptions!$G$71+IF(15>=assumptions!$G$73,assumptions!$G$72,0))+assumptions!$G$74/12)+IF(15=E4,D4*assumptions!$G$75,0),0) -> 8904.2667 | V4: =IF(AND(16>=E4,OR(F4="",16<=F4)),(D4*(1+assumptions!$G$76)^1/12*(1+assumptions!$G$70+assumptions!$G$71+IF(16>=assumptions!$G$73,assumptions!$G$72,0))+assumptions!$G$74/12)+IF(16=E4,D4*assumptions!$G$75,0),0) -> 8904.2667 | W4: =IF(AND(17>=E4,OR(F4="",17<=F4)),(D4*(1+assumptions!$G$76)^1/12*(1+assumptions!$G$70+assumptions!$G$71+IF(17>=assumptions!$G$73,assumptions!$G$72,0))+assumptions!$G$74/12)+IF(17=E4,D4*assumptions!$G$75,0),0) -> 8904.2667 | X4: =IF(AND(18>=E4,OR(F4="",18<=F4)),(D4*(1+assumptions!$G$76)^1/12*(1+assumptions!$G$70+assumptions!$G$71+IF(18>=assumptions!$G$73,assumptions!$G$72,0))+assumptions!$G$74/12)+IF(18=E4,D4*assumptions!$G$75,0),0) -> 8904.2667 | Y4: =IF(AND(19>=E4,OR(F4="",19<=F4)),(D4*(1+assumptions!$G$76)^1/12*(1+assumptions!$G$70+assumptions!$G$71+IF(19>=assumptions!$G$73,assumptions!$G$72,0))+assumptions!$G$74/12)+IF(19=E4,D4*assumptions!$G$75,0),0) -> 8904.2667 | Z4: =IF(AND(20>=E4,OR(F4="",20<=F4)),(D4*(1+assumptions!$G$76)^1/12*(1+assumptions!$G$70+assumptions!$G$71+IF(20>=assumptions!$G$73,assumptions!$G$72,0))+assumptions!$G$74/12)+IF(20=E4,D4*assumptions!$G$75,0),0) -> 8904.2667 | AA4: =IF(AND(21>=E4,OR(F4="",21<=F4)),(D4*(1+assumptions!$G$76)^1/12*(1+assumptions!$G$70+assumptions!$G$71+IF(21>=assumptions!$G$73,assumptions!$G$72,0))+assumptions!$G$74/12)+IF(21=E4,D4*assumptions!$G$75,0),0) -> 8904.2667 | AB4: =IF(AND(22>=E4,OR(F4="",22<=F4)),(D4*(1+assumptions!$G$76)^1/12*(1+assumptions!$G$70+assumptions!$G$71+IF(22>=assumptions!$G$73,assumptions!$G$72,0))+assumptions!$G$74/12)+IF(22=E4,D4*assumptions!$G$75,0),0) -> 8904.2667 | AC4: =IF(AND(23>=E4,OR(F4="",23<=F4)),(D4*(1+assumptions!$G$76)^1/12*(1+assumptions!$G$70+assumptions!$G$71+IF(23>=assumptions!$G$73,assumptions!$G$72,0))+assumptions!$G$74/12)+IF(23=E4,D4*assumptions!$G$75,0),0) -> 8904.2667 | AD4: =IF(AND(24>=E4,OR(F4="",24<=F4)),(D4*(1+assumptions!$G$76)^1/12*(1+assumptions!$G$70+assumptions!$G$71+IF(24>=assumptions!$G$73,assumptions!$G$72,0))+assumptions!$G$74/12)+IF(24=E4,D4*assumptions!$G$75,0),0) -> 8941.1 | AE4: =IF(AND(25>=E4,OR(F4="",25<=F4)),(D4*(1+assumptions!$G$76)^2/12*(1+assumptions!$G$70+assumptions!$G$71+IF(25>=assumptions!$G$73,assumptions!$G$72,0))+assumptions!$G$74/12)+IF(25=E4,D4*assumptions!$G$75,0),0) -> 9286.744 | AF4: =IF(AND(26>=E4,OR(F4="",26<=F4)),(D4*(1+assumptions!$G$76)^2/12*(1+assumptions!$G$70+assumptions!$G$71+IF(26>=assumptions!$G$73,assumptions!$G$72,0))+assumptions!$G$74/12)+IF(26=E4,D4*assumptions!$G$75,0),0) -> 9286.744 | AG4: =IF(AND(27>=E4,OR(F4="",27<=F4)),(D4*(1+assumptions!$G$76)^2/12*(1+assumptions!$G$70+assumptions!$G$71+IF(27>=assumptions!$G$73,assumptions!$G$72,0))+assumptions!$G$74/12)+IF(27=E4,D4*assumptions!$G$75,0),0) -> 9286.744 | AH4: =IF(AND(28>=E4,OR(F4="",28<=F4)),(D4*(1+assumptions!$G$76)^2/12*(1+assumptions!$G$70+assumptions!$G$71+IF(28>=assumptions!$G$73,assumptions!$G$72,0))+assumptions!$G$74/12)+IF(28=E4,D4*assumptions!$G$75,0),0) -> 9286.744 | AI4: =IF(AND(29>=E4,OR(F4="",29<=F4)),(D4*(1+assumptions!$G$76)^2/12*(1+assumptions!$G$70+assumptions!$G$71+IF(29>=assumptions!$G$73,assumptions!$G$72,0))+assumptions!$G$74/12)+IF(29=E4,D4*assumptions!$G$75,0),0) -> 9286.744 | AJ4: =IF(AND(30>=E4,OR(F4="",30<=F4)),(D4*(1+assumptions!$G$76)^2/12*(1+assumptions!$G$70+assumptions!$G$71+IF(30>=assumptions!$G$73,assumptions!$G$72,0))+assumptions!$G$74/12)+IF(30=E4,D4*assumptions!$G$75,0),0) -> 9286.744 | AK4: =IF(AND(31>=E4,OR(F4="",31<=F4)),(D4*(1+assumptions!$G$76)^2/12*(1+assumptions!$G$70+assumptions!$G$71+IF(31>=assumptions!$G$73,assumptions!$G$72,0))+assumptions!$G$74/12)+IF(31=E4,D4*assumptions!$G$75,0),0) -> 9286.744 | AL4: =IF(AND(32>=E4,OR(F4="",32<=F4)),(D4*(1+assumptions!$G$76)^2/12*(1+assumptions!$G$70+assumptions!$G$71+IF(32>=assumptions!$G$73,assumptions!$G$72,0))+assumptions!$G$74/12)+IF(32=E4,D4*assumptions!$G$75,0),0) -> 9286.744 | AM4: =IF(AND(33>=E4,OR(F4="",33<=F4)),(D4*(1+assumptions!$G$76)^2/12*(1+assumptions!$G$70+assumptions!$G$71+IF(33>=assumptions!$G$73,assumptions!$G$72,0))+assumptions!$G$74/12)+IF(33=E4,D4*assumptions!$G$75,0),0) -> 9286.744 | AN4: =IF(AND(34>=E4,OR(F4="",34<=F4)),(D4*(1+assumptions!$G$76)^2/12*(1+assumptions!$G$70+assumptions!$G$71+IF(34>=assumptions!$G$73,assumptions!$G$72,0))+assumptions!$G$74/12)+IF(34=E4,D4*assumptions!$G$75,0),0) -> 9286.744 | AO4: =IF(AND(35>=E4,OR(F4="",35<=F4)),(D4*(1+assumptions!$G$76)^2/12*(1+assumptions!$G$70+assumptions!$G$71+IF(35>=assumptions!$G$73,assumptions!$G$72,0))+assumptions!$G$74/12)+IF(35=E4,D4*assumptions!$G$75,0),0) -> 9286.744 | AP4: =IF(AND(36>=E4,OR(F4="",36<=F4)),(D4*(1+assumptions!$G$76)^2/12*(1+assumptions!$G$70+assumptions!$G$71+IF(36>=assumptions!$G$73,assumptions!$G$72,0))+assumptions!$G$74/12)+IF(36=E4,D4*assumptions!$G$75,0),0) -> 9286.744 | AQ4: =IF(AND(37>=E4,OR(F4="",37<=F4)),(D4*(1+assumptions!$G$76)^3/12*(1+assumptions!$G$70+assumptions!$G$71+IF(37>=assumptions!$G$73,assumptions!$G$72,0))+assumptions!$G$74/12)+IF(37=E4,D4*assumptions!$G$75,0),0) -> 9646.2138 | AR4: =IF(AND(38>=E4,OR(F4="",38<=F4)),(D4*(1+assumptions!$G$76)^3/12*(1+assumptions!$G$70+assumptions!$G$71+IF(38>=assumptions!$G$73,assumptions!$G$72,0))+assumptions!$G$74/12)+IF(38=E4,D4*assumptions!$G$75,0),0) -> 9646.2138 | AS4: =IF(AND(39>=E4,OR(F4="",39<=F4)),(D4*(1+assumptions!$G$76)^3/12*(1+assumptions!$G$70+assumptions!$G$71+IF(39>=assumptions!$G$73,assumptions!$G$72,0))+assumptions!$G$74/12)+IF(39=E4,D4*assumptions!$G$75,0),0) -> 9646.2138 | AT4: =IF(AND(40>=E4,OR(F4="",40<=F4)),(D4*(1+assumptions!$G$76)^3/12*(1+assumptions!$G$70+assumptions!$G$71+IF(40>=assumptions!$G$73,assumptions!$G$72,0))+assumptions!$G$74/12)+IF(40=E4,D4*assumptions!$G$75,0),0) -> 9646.2138 | AU4: =IF(AND(41>=E4,OR(F4="",41<=F4)),(D4*(1+assumptions!$G$76)^3/12*(1+assumptions!$G$70+assumptions!$G$71+IF(41>=assumptions!$G$73,assumptions!$G$72,0))+assumptions!$G$74/12)+IF(41=E4,D4*assumptions!$G$75,0),0) -> 9646.2138 | AV4: =IF(AND(42>=E4,OR(F4="",42<=F4)),(D4*(1+assumptions!$G$76)^3/12*(1+assumptions!$G$70+assumptions!$G$71+IF(42>=assumptions!$G$73,assumptions!$G$72,0))+assumptions!$G$74/12)+IF(42=E4,D4*assumptions!$G$75,0),0) -> 9646.2138 | AW4: =IF(AND(43>=E4,OR(F4="",43<=F4)),(D4*(1+assumptions!$G$76)^3/12*(1+assumptions!$G$70+assumptions!$G$71+IF(43>=assumptions!$G$73,assumptions!$G$72,0))+assumptions!$G$74/12)+IF(43=E4,D4*assumptions!$G$75,0),0) -> 9646.2138 | AX4: =IF(AND(44>=E4,OR(F4="",44<=F4)),(D4*(1+assumptions!$G$76)^3/12*(1+assumptions!$G$70+assumptions!$G$71+IF(44>=assumptions!$G$73,assumptions!$G$72,0))+assumptions!$G$74/12)+IF(44=E4,D4*assumptions!$G$75,0),0) -> 9646.2138 | AY4: =IF(AND(45>=E4,OR(F4="",45<=F4)),(D4*(1+assumptions!$G$76)^3/12*(1+assumptions!$G$70+assumptions!$G$71+IF(45>=assumptions!$G$73,assumptions!$G$72,0))+assumptions!$G$74/12)+IF(45=E4,D4*assumptions!$G$75,0),0) -> 9646.2138 | AZ4: =IF(AND(46>=E4,OR(F4="",46<=F4)),(D4*(1+assumptions!$G$76)^3/12*(1+assumptions!$G$70+assumptions!$G$71+IF(46>=assumptions!$G$73,assumptions!$G$72,0))+assumptions!$G$74/12)+IF(46=E4,D4*assumptions!$G$75,0),0) -> 9646.2138 | BA4: =IF(AND(47>=E4,OR(F4="",47<=F4)),(D4*(1+assumptions!$G$76)^3/12*(1+assumptions!$G$70+assumptions!$G$71+IF(47>=assumptions!$G$73,assumptions!$G$72,0))+assumptions!$G$74/12)+IF(47=E4,D4*assumptions!$G$75,0),0) -> 9646.2138 | BB4: =IF(AND(48>=E4,OR(F4="",48<=F4)),(D4*(1+assumptions!$G$76)^3/12*(1+assumptions!$G$70+assumptions!$G$71+IF(48>=assumptions!$G$73,assumptions!$G$72,0))+assumptions!$G$74/12)+IF(48=E4,D4*assumptions!$G$75,0),0) -> 9646.2138 | BC4: =IF(AND(49>=E4,OR(F4="",49<=F4)),(D4*(1+assumptions!$G$76)^4/12*(1+assumptions!$G$70+assumptions!$G$71+IF(49>=assumptions!$G$73,assumptions!$G$72,0))+assumptions!$G$74/12)+IF(49=E4,D4*assumptions!$G$75,0),0) -> 10020.062 | BD4: =IF(AND(50>=E4,OR(F4="",50<=F4)),(D4*(1+assumptions!$G$76)^4/12*(1+assumptions!$G$70+assumptions!$G$71+IF(50>=assumptions!$G$73,assumptions!$G$72,0))+assumptions!$G$74/12)+IF(50=E4,D4*assumptions!$G$75,0),0) -> 10020.062 | BE4: =IF(AND(51>=E4,OR(F4="",51<=F4)),(D4*(1+assumptions!$G$76)^4/12*(1+assumptions!$G$70+assumptions!$G$71+IF(51>=assumptions!$G$73,assumptions!$G$72,0))+assumptions!$G$74/12)+IF(51=E4,D4*assumptions!$G$75,0),0) -> 10020.062 | BF4: =IF(AND(52>=E4,OR(F4="",52<=F4)),(D4*(1+assumptions!$G$76)^4/12*(1+assumptions!$G$70+assumptions!$G$71+IF(52>=assumptions!$G$73,assumptions!$G$72,0))+assumptions!$G$74/12)+IF(52=E4,D4*assumptions!$G$75,0),0) -> 10020.062 | BG4: =IF(AND(53>=E4,OR(F4="",53<=F4)),(D4*(1+assumptions!$G$76)^4/12*(1+assumptions!$G$70+assumptions!$G$71+IF(53>=assumptions!$G$73,assumptions!$G$72,0))+assumptions!$G$74/12)+IF(53=E4,D4*assumptions!$G$75,0),0) -> 10020.062 | BH4: =IF(AND(54>=E4,OR(F4="",54<=F4)),(D4*(1+assumptions!$G$76)^4/12*(1+assumptions!$G$70+assumptions!$G$71+IF(54>=assumptions!$G$73,assumptions!$G$72,0))+assumptions!$G$74/12)+IF(54=E4,D4*assumptions!$G$75,0),0) -> 10020.062 | BI4: =IF(AND(55>=E4,OR(F4="",55<=F4)),(D4*(1+assumptions!$G$76)^4/12*(1+assumptions!$G$70+assumptions!$G$71+IF(55>=assumptions!$G$73,assumptions!$G$72,0))+assumptions!$G$74/12)+IF(55=E4,D4*assumptions!$G$75,0),0) -> 10020.062 | BJ4: =IF(AND(56>=E4,OR(F4="",56<=F4)),(D4*(1+assumptions!$G$76)^4/12*(1+assumptions!$G$70+assumptions!$G$71+IF(56>=assumptions!$G$73,assumptions!$G$72,0))+assumptions!$G$74/12)+IF(56=E4,D4*assumptions!$G$75,0),0) -> 10020.062 | BK4: =IF(AND(57>=E4,OR(F4="",57<=F4)),(D4*(1+assumptions!$G$76)^4/12*(1+assumptions!$G$70+assumptions!$G$71+IF(57>=assumptions!$G$73,assumptions!$G$72,0))+assumptions!$G$74/12)+IF(57=E4,D4*assumptions!$G$75,0),0) -> 10020.062 | BL4: =IF(AND(58>=E4,OR(F4="",58<=F4)),(D4*(1+assumptions!$G$76)^4/12*(1+assumptions!$G$70+assumptions!$G$71+IF(58>=assumptions!$G$73,assumptions!$G$72,0))+assumptions!$G$74/12)+IF(58=E4,D4*assumptions!$G$75,0),0) -> 10020.062 | BM4: =IF(AND(59>=E4,OR(F4="",59<=F4)),(D4*(1+assumptions!$G$76)^4/12*(1+assumptions!$G$70+assumptions!$G$71+IF(59>=assumptions!$G$73,assumptions!$G$72,0))+assumptions!$G$74/12)+IF(59=E4,D4*assumptions!$G$75,0),0) -> 10020.062 | BN4: =IF(AND(60>=E4,OR(F4="",60<=F4)),(D4*(1+assumptions!$G$76)^4/12*(1+assumptions!$G$70+assumptions!$G$71+IF(60>=assumptions!$G$73,assumptions!$G$72,0))+assumptions!$G$74/12)+IF(60=E4,D4*assumptions!$G$75,0),0) -> 10020.062
A5: 2 | B5: CTO / Co-founder | C5: exec | D5: 85000 | E5: 1 | G5: =IF(AND(1>=E5,OR(F5="",1<=F5)),(D5*(1+assumptions!$G$76)^0/12*(1+assumptions!$G$70+assumptions!$G$71+IF(1>=assumptions!$G$73,assumptions!$G$72,0))+assumptions!$G$74/12)+IF(1=E5,D5*assumptions!$G$75,0),0) -> 21323.333 | H5: =IF(AND(2>=E5,OR(F5="",2<=F5)),(D5*(1+assumptions!$G$76)^0/12*(1+assumptions!$G$70+assumptions!$G$71+IF(2>=assumptions!$G$73,assumptions!$G$72,0))+assumptions!$G$74/12)+IF(2=E5,D5*assumptions!$G$75,0),0) -> 8573.3333 | I5: =IF(AND(3>=E5,OR(F5="",3<=F5)),(D5*(1+assumptions!$G$76)^0/12*(1+assumptions!$G$70+assumptions!$G$71+IF(3>=assumptions!$G$73,assumptions!$G$72,0))+assumptions!$G$74/12)+IF(3=E5,D5*assumptions!$G$75,0),0) -> 8573.3333 | J5: =IF(AND(4>=E5,OR(F5="",4<=F5)),(D5*(1+assumptions!$G$76)^0/12*(1+assumptions!$G$70+assumptions!$G$71+IF(4>=assumptions!$G$73,assumptions!$G$72,0))+assumptions!$G$74/12)+IF(4=E5,D5*assumptions!$G$75,0),0) -> 8573.3333 | K5: =IF(AND(5>=E5,OR(F5="",5<=F5)),(D5*(1+assumptions!$G$76)^0/12*(1+assumptions!$G$70+assumptions!$G$71+IF(5>=assumptions!$G$73,assumptions!$G$72,0))+assumptions!$G$74/12)+IF(5=E5,D5*assumptions!$G$75,0),0) -> 8573.3333 | L5: =IF(AND(6>=E5,OR(F5="",6<=F5)),(D5*(1+assumptions!$G$76)^0/12*(1+assumptions!$G$70+assumptions!$G$71+IF(6>=assumptions!$G$73,assumptions!$G$72,0))+assumptions!$G$74/12)+IF(6=E5,D5*assumptions!$G$75,0),0) -> 8573.3333 | M5: =IF(AND(7>=E5,OR(F5="",7<=F5)),(D5*(1+assumptions!$G$76)^0/12*(1+assumptions!$G$70+assumptions!$G$71+IF(7>=assumptions!$G$73,assumptions!$G$72,0))+assumptions!$G$74/12)+IF(7=E5,D5*assumptions!$G$75,0),0) -> 8573.3333 | N5: =IF(AND(8>=E5,OR(F5="",8<=F5)),(D5*(1+assumptions!$G$76)^0/12*(1+assumptions!$G$70+assumptions!$G$71+IF(8>=assumptions!$G$73,assumptions!$G$72,0))+assumptions!$G$74/12)+IF(8=E5,D5*assumptions!$G$75,0),0) -> 8573.3333 | O5: =IF(AND(9>=E5,OR(F5="",9<=F5)),(D5*(1+assumptions!$G$76)^0/12*(1+assumptions!$G$70+assumptions!$G$71+IF(9>=assumptions!$G$73,assumptions!$G$72,0))+assumptions!$G$74/12)+IF(9=E5,D5*assumptions!$G$75,0),0) -> 8573.3333 | P5: =IF(AND(10>=E5,OR(F5="",10<=F5)),(D5*(1+assumptions!$G$76)^0/12*(1+assumptions!$G$70+assumptions!$G$71+IF(10>=assumptions!$G$73,assumptions!$G$72,0))+assumptions!$G$74/12)+IF(10=E5,D5*assumptions!$G$75,0),0) -> 8573.3333 | Q5: =IF(AND(11>=E5,OR(F5="",11<=F5)),(D5*(1+assumptions!$G$76)^0/12*(1+assumptions!$G$70+assumptions!$G$71+IF(11>=assumptions!$G$73,assumptions!$G$72,0))+assumptions!$G$74/12)+IF(11=E5,D5*assumptions!$G$75,0),0) -> 8573.3333 | R5: =IF(AND(12>=E5,OR(F5="",12<=F5)),(D5*(1+assumptions!$G$76)^0/12*(1+assumptions!$G$70+assumptions!$G$71+IF(12>=assumptions!$G$73,assumptions!$G$72,0))+assumptions!$G$74/12)+IF(12=E5,D5*assumptions!$G$75,0),0) -> 8573.3333 | S5: =IF(AND(13>=E5,OR(F5="",13<=F5)),(D5*(1+assumptions!$G$76)^1/12*(1+assumptions!$G$70+assumptions!$G$71+IF(13>=assumptions!$G$73,assumptions!$G$72,0))+assumptions!$G$74/12)+IF(13=E5,D5*assumptions!$G$75,0),0) -> 8904.2667 | T5: =IF(AND(14>=E5,OR(F5="",14<=F5)),(D5*(1+assumptions!$G$76)^1/12*(1+assumptions!$G$70+assumptions!$G$71+IF(14>=assumptions!$G$73,assumptions!$G$72,0))+assumptions!$G$74/12)+IF(14=E5,D5*assumptions!$G$75,0),0) -> 8904.2667 | U5: =IF(AND(15>=E5,OR(F5="",15<=F5)),(D5*(1+assumptions!$G$76)^1/12*(1+assumptions!$G$70+assumptions!$G$71+IF(15>=assumptions!$G$73,assumptions!$G$72,0))+assumptions!$G$74/12)+IF(15=E5,D5*assumptions!$G$75,0),0) -> 8904.2667 | V5: =IF(AND(16>=E5,OR(F5="",16<=F5)),(D5*(1+assumptions!$G$76)^1/12*(1+assumptions!$G$70+assumptions!$G$71+IF(16>=assumptions!$G$73,assumptions!$G$72,0))+assumptions!$G$74/12)+IF(16=E5,D5*assumptions!$G$75,0),0) -> 8904.2667 | W5: =IF(AND(17>=E5,OR(F5="",17<=F5)),(D5*(1+assumptions!$G$76)^1/12*(1+assumptions!$G$70+assumptions!$G$71+IF(17>=assumptions!$G$73,assumptions!$G$72,0))+assumptions!$G$74/12)+IF(17=E5,D5*assumptions!$G$75,0),0) -> 8904.2667 | X5: =IF(AND(18>=E5,OR(F5="",18<=F5)),(D5*(1+assumptions!$G$76)^1/12*(1+assumptions!$G$70+assumptions!$G$71+IF(18>=assumptions!$G$73,assumptions!$G$72,0))+assumptions!$G$74/12)+IF(18=E5,D5*assumptions!$G$75,0),0) -> 8904.2667 | Y5: =IF(AND(19>=E5,OR(F5="",19<=F5)),(D5*(1+assumptions!$G$76)^1/12*(1+assumptions!$G$70+assumptions!$G$71+IF(19>=assumptions!$G$73,assumptions!$G$72,0))+assumptions!$G$74/12)+IF(19=E5,D5*assumptions!$G$75,0),0) -> 8904.2667 | Z5: =IF(AND(20>=E5,OR(F5="",20<=F5)),(D5*(1+assumptions!$G$76)^1/12*(1+assumptions!$G$70+assumptions!$G$71+IF(20>=assumptions!$G$73,assumptions!$G$72,0))+assumptions!$G$74/12)+IF(20=E5,D5*assumptions!$G$75,0),0) -> 8904.2667 | AA5: =IF(AND(21>=E5,OR(F5="",21<=F5)),(D5*(1+assumptions!$G$76)^1/12*(1+assumptions!$G$70+assumptions!$G$71+IF(21>=assumptions!$G$73,assumptions!$G$72,0))+assumptions!$G$74/12)+IF(21=E5,D5*assumptions!$G$75,0),0) -> 8904.2667 | AB5: =IF(AND(22>=E5,OR(F5="",22<=F5)),(D5*(1+assumptions!$G$76)^1/12*(1+assumptions!$G$70+assumptions!$G$71+IF(22>=assumptions!$G$73,assumptions!$G$72,0))+assumptions!$G$74/12)+IF(22=E5,D5*assumptions!$G$75,0),0) -> 8904.2667 | AC5: =IF(AND(23>=E5,OR(F5="",23<=F5)),(D5*(1+assumptions!$G$76)^1/12*(1+assumptions!$G$70+assumptions!$G$71+IF(23>=assumptions!$G$73,assumptions!$G$72,0))+assumptions!$G$74/12)+IF(23=E5,D5*assumptions!$G$75,0),0) -> 8904.2667 | AD5: =IF(AND(24>=E5,OR(F5="",24<=F5)),(D5*(1+assumptions!$G$76)^1/12*(1+assumptions!$G$70+assumptions!$G$71+IF(24>=assumptions!$G$73,assumptions!$G$72,0))+assumptions!$G$74/12)+IF(24=E5,D5*assumptions!$G$75,0),0) -> 8941.1 | AE5: =IF(AND(25>=E5,OR(F5="",25<=F5)),(D5*(1+assumptions!$G$76)^2/12*(1+assumptions!$G$70+assumptions!$G$71+IF(25>=assumptions!$G$73,assumptions!$G$72,0))+assumptions!$G$74/12)+IF(25=E5,D5*assumptions!$G$75,0),0) -> 9286.744 | AF5: =IF(AND(26>=E5,OR(F5="",26<=F5)),(D5*(1+assumptions!$G$76)^2/12*(1+assumptions!$G$70+assumptions!$G$71+IF(26>=assumptions!$G$73,assumptions!$G$72,0))+assumptions!$G$74/12)+IF(26=E5,D5*assumptions!$G$75,0),0) -> 9286.744 | AG5: =IF(AND(27>=E5,OR(F5="",27<=F5)),(D5*(1+assumptions!$G$76)^2/12*(1+assumptions!$G$70+assumptions!$G$71+IF(27>=assumptions!$G$73,assumptions!$G$72,0))+assumptions!$G$74/12)+IF(27=E5,D5*assumptions!$G$75,0),0) -> 9286.744 | AH5: =IF(AND(28>=E5,OR(F5="",28<=F5)),(D5*(1+assumptions!$G$76)^2/12*(1+assumptions!$G$70+assumptions!$G$71+IF(28>=assumptions!$G$73,assumptions!$G$72,0))+assumptions!$G$74/12)+IF(28=E5,D5*assumptions!$G$75,0),0) -> 9286.744 | AI5: =IF(AND(29>=E5,OR(F5="",29<=F5)),(D5*(1+assumptions!$G$76)^2/12*(1+assumptions!$G$70+assumptions!$G$71+IF(29>=assumptions!$G$73,assumptions!$G$72,0))+assumptions!$G$74/12)+IF(29=E5,D5*assumptions!$G$75,0),0) -> 9286.744 | AJ5: =IF(AND(30>=E5,OR(F5="",30<=F5)),(D5*(1+assumptions!$G$76)^2/12*(1+assumptions!$G$70+assumptions!$G$71+IF(30>=assumptions!$G$73,assumptions!$G$72,0))+assumptions!$G$74/12)+IF(30=E5,D5*assumptions!$G$75,0),0) -> 9286.744 | AK5: =IF(AND(31>=E5,OR(F5="",31<=F5)),(D5*(1+assumptions!$G$76)^2/12*(1+assumptions!$G$70+assumptions!$G$71+IF(31>=assumptions!$G$73,assumptions!$G$72,0))+assumptions!$G$74/12)+IF(31=E5,D5*assumptions!$G$75,0),0) -> 9286.744 | AL5: =IF(AND(32>=E5,OR(F5="",32<=F5)),(D5*(1+assumptions!$G$76)^2/12*(1+assumptions!$G$70+assumptions!$G$71+IF(32>=assumptions!$G$73,assumptions!$G$72,0))+assumptions!$G$74/12)+IF(32=E5,D5*assumptions!$G$75,0),0) -> 9286.744 | AM5: =IF(AND(33>=E5,OR(F5="",33<=F5)),(D5*(1+assumptions!$G$76)^2/12*(1+assumptions!$G$70+assumptions!$G$71+IF(33>=assumptions!$G$73,assumptions!$G$72,0))+assumptions!$G$74/12)+IF(33=E5,D5*assumptions!$G$75,0),0) -> 9286.744 | AN5: =IF(AND(34>=E5,OR(F5="",34<=F5)),(D5*(1+assumptions!$G$76)^2/12*(1+assumptions!$G$70+assumptions!$G$71+IF(34>=assumptions!$G$73,assumptions!$G$72,0))+assumptions!$G$74/12)+IF(34=E5,D5*assumptions!$G$75,0),0) -> 9286.744 | AO5: =IF(AND(35>=E5,OR(F5="",35<=F5)),(D5*(1+assumptions!$G$76)^2/12*(1+assumptions!$G$70+assumptions!$G$71+IF(35>=assumptions!$G$73,assumptions!$G$72,0))+assumptions!$G$74/12)+IF(35=E5,D5*assumptions!$G$75,0),0) -> 9286.744 | AP5: =IF(AND(36>=E5,OR(F5="",36<=F5)),(D5*(1+assumptions!$G$76)^2/12*(1+assumptions!$G$70+assumptions!$G$71+IF(36>=assumptions!$G$73,assumptions!$G$72,0))+assumptions!$G$74/12)+IF(36=E5,D5*assumptions!$G$75,0),0) -> 9286.744 | AQ5: =IF(AND(37>=E5,OR(F5="",37<=F5)),(D5*(1+assumptions!$G$76)^3/12*(1+assumptions!$G$70+assumptions!$G$71+IF(37>=assumptions!$G$73,assumptions!$G$72,0))+assumptions!$G$74/12)+IF(37=E5,D5*assumptions!$G$75,0),0) -> 9646.2138 | AR5: =IF(AND(38>=E5,OR(F5="",38<=F5)),(D5*(1+assumptions!$G$76)^3/12*(1+assumptions!$G$70+assumptions!$G$71+IF(38>=assumptions!$G$73,assumptions!$G$72,0))+assumptions!$G$74/12)+IF(38=E5,D5*assumptions!$G$75,0),0) -> 9646.2138 | AS5: =IF(AND(39>=E5,OR(F5="",39<=F5)),(D5*(1+assumptions!$G$76)^3/12*(1+assumptions!$G$70+assumptions!$G$71+IF(39>=assumptions!$G$73,assumptions!$G$72,0))+assumptions!$G$74/12)+IF(39=E5,D5*assumptions!$G$75,0),0) -> 9646.2138 | AT5: =IF(AND(40>=E5,OR(F5="",40<=F5)),(D5*(1+assumptions!$G$76)^3/12*(1+assumptions!$G$70+assumptions!$G$71+IF(40>=assumptions!$G$73,assumptions!$G$72,0))+assumptions!$G$74/12)+IF(40=E5,D5*assumptions!$G$75,0),0) -> 9646.2138 | AU5: =IF(AND(41>=E5,OR(F5="",41<=F5)),(D5*(1+assumptions!$G$76)^3/12*(1+assumptions!$G$70+assumptions!$G$71+IF(41>=assumptions!$G$73,assumptions!$G$72,0))+assumptions!$G$74/12)+IF(41=E5,D5*assumptions!$G$75,0),0) -> 9646.2138 | AV5: =IF(AND(42>=E5,OR(F5="",42<=F5)),(D5*(1+assumptions!$G$76)^3/12*(1+assumptions!$G$70+assumptions!$G$71+IF(42>=assumptions!$G$73,assumptions!$G$72,0))+assumptions!$G$74/12)+IF(42=E5,D5*assumptions!$G$75,0),0) -> 9646.2138 | AW5: =IF(AND(43>=E5,OR(F5="",43<=F5)),(D5*(1+assumptions!$G$76)^3/12*(1+assumptions!$G$70+assumptions!$G$71+IF(43>=assumptions!$G$73,assumptions!$G$72,0))+assumptions!$G$74/12)+IF(43=E5,D5*assumptions!$G$75,0),0) -> 9646.2138 | AX5: =IF(AND(44>=E5,OR(F5="",44<=F5)),(D5*(1+assumptions!$G$76)^3/12*(1+assumptions!$G$70+assumptions!$G$71+IF(44>=assumptions!$G$73,assumptions!$G$72,0))+assumptions!$G$74/12)+IF(44=E5,D5*assumptions!$G$75,0),0) -> 9646.2138 | AY5: =IF(AND(45>=E5,OR(F5="",45<=F5)),(D5*(1+assumptions!$G$76)^3/12*(1+assumptions!$G$70+assumptions!$G$71+IF(45>=assumptions!$G$73,assumptions!$G$72,0))+assumptions!$G$74/12)+IF(45=E5,D5*assumptions!$G$75,0),0) -> 9646.2138 | AZ5: =IF(AND(46>=E5,OR(F5="",46<=F5)),(D5*(1+assumptions!$G$76)^3/12*(1+assumptions!$G$70+assumptions!$G$71+IF(46>=assumptions!$G$73,assumptions!$G$72,0))+assumptions!$G$74/12)+IF(46=E5,D5*assumptions!$G$75,0),0) -> 9646.2138 | BA5: =IF(AND(47>=E5,OR(F5="",47<=F5)),(D5*(1+assumptions!$G$76)^3/12*(1+assumptions!$G$70+assumptions!$G$71+IF(47>=assumptions!$G$73,assumptions!$G$72,0))+assumptions!$G$74/12)+IF(47=E5,D5*assumptions!$G$75,0),0) -> 9646.2138 | BB5: =IF(AND(48>=E5,OR(F5="",48<=F5)),(D5*(1+assumptions!$G$76)^3/12*(1+assumptions!$G$70+assumptions!$G$71+IF(48>=assumptions!$G$73,assumptions!$G$72,0))+assumptions!$G$74/12)+IF(48=E5,D5*assumptions!$G$75,0),0) -> 9646.2138 | BC5: =IF(AND(49>=E5,OR(F5="",49<=F5)),(D5*(1+assumptions!$G$76)^4/12*(1+assumptions!$G$70+assumptions!$G$71+IF(49>=assumptions!$G$73,assumptions!$G$72,0))+assumptions!$G$74/12)+IF(49=E5,D5*assumptions!$G$75,0),0) -> 10020.062 | BD5: =IF(AND(50>=E5,OR(F5="",50<=F5)),(D5*(1+assumptions!$G$76)^4/12*(1+assumptions!$G$70+assumptions!$G$71+IF(50>=assumptions!$G$73,assumptions!$G$72,0))+assumptions!$G$74/12)+IF(50=E5,D5*assumptions!$G$75,0),0) -> 10020.062 | BE5: =IF(AND(51>=E5,OR(F5="",51<=F5)),(D5*(1+assumptions!$G$76)^4/12*(1+assumptions!$G$70+assumptions!$G$71+IF(51>=assumptions!$G$73,assumptions!$G$72,0))+assumptions!$G$74/12)+IF(51=E5,D5*assumptions!$G$75,0),0) -> 10020.062 | BF5: =IF(AND(52>=E5,OR(F5="",52<=F5)),(D5*(1+assumptions!$G$76)^4/12*(1+assumptions!$G$70+assumptions!$G$71+IF(52>=assumptions!$G$73,assumptions!$G$72,0))+assumptions!$G$74/12)+IF(52=E5,D5*assumptions!$G$75,0),0) -> 10020.062 | BG5: =IF(AND(53>=E5,OR(F5="",53<=F5)),(D5*(1+assumptions!$G$76)^4/12*(1+assumptions!$G$70+assumptions!$G$71+IF(53>=assumptions!$G$73,assumptions!$G$72,0))+assumptions!$G$74/12)+IF(53=E5,D5*assumptions!$G$75,0),0) -> 10020.062 | BH5: =IF(AND(54>=E5,OR(F5="",54<=F5)),(D5*(1+assumptions!$G$76)^4/12*(1+assumptions!$G$70+assumptions!$G$71+IF(54>=assumptions!$G$73,assumptions!$G$72,0))+assumptions!$G$74/12)+IF(54=E5,D5*assumptions!$G$75,0),0) -> 10020.062 | BI5: =IF(AND(55>=E5,OR(F5="",55<=F5)),(D5*(1+assumptions!$G$76)^4/12*(1+assumptions!$G$70+assumptions!$G$71+IF(55>=assumptions!$G$73,assumptions!$G$72,0))+assumptions!$G$74/12)+IF(55=E5,D5*assumptions!$G$75,0),0) -> 10020.062 | BJ5: =IF(AND(56>=E5,OR(F5="",56<=F5)),(D5*(1+assumptions!$G$76)^4/12*(1+assumptions!$G$70+assumptions!$G$71+IF(56>=assumptions!$G$73,assumptions!$G$72,0))+assumptions!$G$74/12)+IF(56=E5,D5*assumptions!$G$75,0),0) -> 10020.062 | BK5: =IF(AND(57>=E5,OR(F5="",57<=F5)),(D5*(1+assumptions!$G$76)^4/12*(1+assumptions!$G$70+assumptions!$G$71+IF(57>=assumptions!$G$73,assumptions!$G$72,0))+assumptions!$G$74/12)+IF(57=E5,D5*assumptions!$G$75,0),0) -> 10020.062 | BL5: =IF(AND(58>=E5,OR(F5="",58<=F5)),(D5*(1+assumptions!$G$76)^4/12*(1+assumptions!$G$70+assumptions!$G$71+IF(58>=assumptions!$G$73,assumptions!$G$72,0))+assumptions!$G$74/12)+IF(58=E5,D5*assumptions!$G$75,0),0) -> 10020.062 | BM5: =IF(AND(59>=E5,OR(F5="",59<=F5)),(D5*(1+assumptions!$G$76)^4/12*(1+assumptions!$G$70+assumptions!$G$71+IF(59>=assumptions!$G$73,assumptions!$G$72,0))+assumptions!$G$74/12)+IF(59=E5,D5*assumptions!$G$75,0),0) -> 10020.062 | BN5: =IF(AND(60>=E5,OR(F5="",60<=F5)),(D5*(1+assumptions!$G$76)^4/12*(1+assumptions!$G$70+assumptions!$G$71+IF(60>=assumptions!$G$73,assumptions!$G$72,0))+assumptions!$G$74/12)+IF(60=E5,D5*assumptions!$G$75,0),0) -> 10020.062
A6: 3 | B6: Founding engineer | C6: eng | D6: 80000 | E6: 1 | G6: =IF(AND(1>=E6,OR(F6="",1<=F6)),(D6*(1+assumptions!$G$76)^0/12*(1+assumptions!$G$70+assumptions!$G$71+IF(1>=assumptions!$G$73,assumptions!$G$72,0))+assumptions!$G$74/12)+IF(1=E6,D6*assumptions!$G$75,0),0) -> 20086.667 | H6: =IF(AND(2>=E6,OR(F6="",2<=F6)),(D6*(1+assumptions!$G$76)^0/12*(1+assumptions!$G$70+assumptions!$G$71+IF(2>=assumptions!$G$73,assumptions!$G$72,0))+assumptions!$G$74/12)+IF(2=E6,D6*assumptions!$G$75,0),0) -> 8086.6667 | I6: =IF(AND(3>=E6,OR(F6="",3<=F6)),(D6*(1+assumptions!$G$76)^0/12*(1+assumptions!$G$70+assumptions!$G$71+IF(3>=assumptions!$G$73,assumptions!$G$72,0))+assumptions!$G$74/12)+IF(3=E6,D6*assumptions!$G$75,0),0) -> 8086.6667 | J6: =IF(AND(4>=E6,OR(F6="",4<=F6)),(D6*(1+assumptions!$G$76)^0/12*(1+assumptions!$G$70+assumptions!$G$71+IF(4>=assumptions!$G$73,assumptions!$G$72,0))+assumptions!$G$74/12)+IF(4=E6,D6*assumptions!$G$75,0),0) -> 8086.6667 | K6: =IF(AND(5>=E6,OR(F6="",5<=F6)),(D6*(1+assumptions!$G$76)^0/12*(1+assumptions!$G$70+assumptions!$G$71+IF(5>=assumptions!$G$73,assumptions!$G$72,0))+assumptions!$G$74/12)+IF(5=E6,D6*assumptions!$G$75,0),0) -> 8086.6667 | L6: =IF(AND(6>=E6,OR(F6="",6<=F6)),(D6*(1+assumptions!$G$76)^0/12*(1+assumptions!$G$70+assumptions!$G$71+IF(6>=assumptions!$G$73,assumptions!$G$72,0))+assumptions!$G$74/12)+IF(6=E6,D6*assumptions!$G$75,0),0) -> 8086.6667 | M6: =IF(AND(7>=E6,OR(F6="",7<=F6)),(D6*(1+assumptions!$G$76)^0/12*(1+assumptions!$G$70+assumptions!$G$71+IF(7>=assumptions!$G$73,assumptions!$G$72,0))+assumptions!$G$74/12)+IF(7=E6,D6*assumptions!$G$75,0),0) -> 8086.6667 | N6: =IF(AND(8>=E6,OR(F6="",8<=F6)),(D6*(1+assumptions!$G$76)^0/12*(1+assumptions!$G$70+assumptions!$G$71+IF(8>=assumptions!$G$73,assumptions!$G$72,0))+assumptions!$G$74/12)+IF(8=E6,D6*assumptions!$G$75,0),0) -> 8086.6667 | O6: =IF(AND(9>=E6,OR(F6="",9<=F6)),(D6*(1+assumptions!$G$76)^0/12*(1+assumptions!$G$70+assumptions!$G$71+IF(9>=assumptions!$G$73,assumptions!$G$72,0))+assumptions!$G$74/12)+IF(9=E6,D6*assumptions!$G$75,0),0) -> 8086.6667 | P6: =IF(AND(10>=E6,OR(F6="",10<=F6)),(D6*(1+assumptions!$G$76)^0/12*(1+assumptions!$G$70+assumptions!$G$71+IF(10>=assumptions!$G$73,assumptions!$G$72,0))+assumptions!$G$74/12)+IF(10=E6,D6*assumptions!$G$75,0),0) -> 8086.6667 | Q6: =IF(AND(11>=E6,OR(F6="",11<=F6)),(D6*(1+assumptions!$G$76)^0/12*(1+assumptions!$G$70+assumptions!$G$71+IF(11>=assumptions!$G$73,assumptions!$G$72,0))+assumptions!$G$74/12)+IF(11=E6,D6*assumptions!$G$75,0),0) -> 8086.6667 | R6: =IF(AND(12>=E6,OR(F6="",12<=F6)),(D6*(1+assumptions!$G$76)^0/12*(1+assumptions!$G$70+assumptions!$G$71+IF(12>=assumptions!$G$73,assumptions!$G$72,0))+assumptions!$G$74/12)+IF(12=E6,D6*assumptions!$G$75,0),0) -> 8086.6667 | S6: =IF(AND(13>=E6,OR(F6="",13<=F6)),(D6*(1+assumptions!$G$76)^1/12*(1+assumptions!$G$70+assumptions!$G$71+IF(13>=assumptions!$G$73,assumptions!$G$72,0))+assumptions!$G$74/12)+IF(13=E6,D6*assumptions!$G$75,0),0) -> 8398.1333 | T6: =IF(AND(14>=E6,OR(F6="",14<=F6)),(D6*(1+assumptions!$G$76)^1/12*(1+assumptions!$G$70+assumptions!$G$71+IF(14>=assumptions!$G$73,assumptions!$G$72,0))+assumptions!$G$74/12)+IF(14=E6,D6*assumptions!$G$75,0),0) -> 8398.1333 | U6: =IF(AND(15>=E6,OR(F6="",15<=F6)),(D6*(1+assumptions!$G$76)^1/12*(1+assumptions!$G$70+assumptions!$G$71+IF(15>=assumptions!$G$73,assumptions!$G$72,0))+assumptions!$G$74/12)+IF(15=E6,D6*assumptions!$G$75,0),0) -> 8398.1333 | V6: =IF(AND(16>=E6,OR(F6="",16<=F6)),(D6*(1+assumptions!$G$76)^1/12*(1+assumptions!$G$70+assumptions!$G$71+IF(16>=assumptions!$G$73,assumptions!$G$72,0))+assumptions!$G$74/12)+IF(16=E6,D6*assumptions!$G$75,0),0) -> 8398.1333 | W6: =IF(AND(17>=E6,OR(F6="",17<=F6)),(D6*(1+assumptions!$G$76)^1/12*(1+assumptions!$G$70+assumptions!$G$71+IF(17>=assumptions!$G$73,assumptions!$G$72,0))+assumptions!$G$74/12)+IF(17=E6,D6*assumptions!$G$75,0),0) -> 8398.1333 | X6: =IF(AND(18>=E6,OR(F6="",18<=F6)),(D6*(1+assumptions!$G$76)^1/12*(1+assumptions!$G$70+assumptions!$G$71+IF(18>=assumptions!$G$73,assumptions!$G$72,0))+assumptions!$G$74/12)+IF(18=E6,D6*assumptions!$G$75,0),0) -> 8398.1333 | Y6: =IF(AND(19>=E6,OR(F6="",19<=F6)),(D6*(1+assumptions!$G$76)^1/12*(1+assumptions!$G$70+assumptions!$G$71+IF(19>=assumptions!$G$73,assumptions!$G$72,0))+assumptions!$G$74/12)+IF(19=E6,D6*assumptions!$G$75,0),0) -> 8398.1333 | Z6: =IF(AND(20>=E6,OR(F6="",20<=F6)),(D6*(1+assumptions!$G$76)^1/12*(1+assumptions!$G$70+assumptions!$G$71+IF(20>=assumptions!$G$73,assumptions!$G$72,0))+assumptions!$G$74/12)+IF(20=E6,D6*assumptions!$G$75,0),0) -> 8398.1333 | AA6: =IF(AND(21>=E6,OR(F6="",21<=F6)),(D6*(1+assumptions!$G$76)^1/12*(1+assumptions!$G$70+assumptions!$G$71+IF(21>=assumptions!$G$73,assumptions!$G$72,0))+assumptions!$G$74/12)+IF(21=E6,D6*assumptions!$G$75,0),0) -> 8398.1333 | AB6: =IF(AND(22>=E6,OR(F6="",22<=F6)),(D6*(1+assumptions!$G$76)^1/12*(1+assumptions!$G$70+assumptions!$G$71+IF(22>=assumptions!$G$73,assumptions!$G$72,0))+assumptions!$G$74/12)+IF(22=E6,D6*assumptions!$G$75,0),0) -> 8398.1333 | AC6: =IF(AND(23>=E6,OR(F6="",23<=F6)),(D6*(1+assumptions!$G$76)^1/12*(1+assumptions!$G$70+assumptions!$G$71+IF(23>=assumptions!$G$73,assumptions!$G$72,0))+assumptions!$G$74/12)+IF(23=E6,D6*assumptions!$G$75,0),0) -> 8398.1333 | AD6: =IF(AND(24>=E6,OR(F6="",24<=F6)),(D6*(1+assumptions!$G$76)^1/12*(1+assumptions!$G$70+assumptions!$G$71+IF(24>=assumptions!$G$73,assumptions!$G$72,0))+assumptions!$G$74/12)+IF(24=E6,D6*assumptions!$G$75,0),0) -> 8432.8 | AE6: =IF(AND(25>=E6,OR(F6="",25<=F6)),(D6*(1+assumptions!$G$76)^2/12*(1+assumptions!$G$70+assumptions!$G$71+IF(25>=assumptions!$G$73,assumptions!$G$72,0))+assumptions!$G$74/12)+IF(25=E6,D6*assumptions!$G$75,0),0) -> 8758.112 | AF6: =IF(AND(26>=E6,OR(F6="",26<=F6)),(D6*(1+assumptions!$G$76)^2/12*(1+assumptions!$G$70+assumptions!$G$71+IF(26>=assumptions!$G$73,assumptions!$G$72,0))+assumptions!$G$74/12)+IF(26=E6,D6*assumptions!$G$75,0),0) -> 8758.112 | AG6: =IF(AND(27>=E6,OR(F6="",27<=F6)),(D6*(1+assumptions!$G$76)^2/12*(1+assumptions!$G$70+assumptions!$G$71+IF(27>=assumptions!$G$73,assumptions!$G$72,0))+assumptions!$G$74/12)+IF(27=E6,D6*assumptions!$G$75,0),0) -> 8758.112 | AH6: =IF(AND(28>=E6,OR(F6="",28<=F6)),(D6*(1+assumptions!$G$76)^2/12*(1+assumptions!$G$70+assumptions!$G$71+IF(28>=assumptions!$G$73,assumptions!$G$72,0))+assumptions!$G$74/12)+IF(28=E6,D6*assumptions!$G$75,0),0) -> 8758.112 | AI6: =IF(AND(29>=E6,OR(F6="",29<=F6)),(D6*(1+assumptions!$G$76)^2/12*(1+assumptions!$G$70+assumptions!$G$71+IF(29>=assumptions!$G$73,assumptions!$G$72,0))+assumptions!$G$74/12)+IF(29=E6,D6*assumptions!$G$75,0),0) -> 8758.112 | AJ6: =IF(AND(30>=E6,OR(F6="",30<=F6)),(D6*(1+assumptions!$G$76)^2/12*(1+assumptions!$G$70+assumptions!$G$71+IF(30>=assumptions!$G$73,assumptions!$G$72,0))+assumptions!$G$74/12)+IF(30=E6,D6*assumptions!$G$75,0),0) -> 8758.112 | AK6: =IF(AND(31>=E6,OR(F6="",31<=F6)),(D6*(1+assumptions!$G$76)^2/12*(1+assumptions!$G$70+assumptions!$G$71+IF(31>=assumptions!$G$73,assumptions!$G$72,0))+assumptions!$G$74/12)+IF(31=E6,D6*assumptions!$G$75,0),0) -> 8758.112 | AL6: =IF(AND(32>=E6,OR(F6="",32<=F6)),(D6*(1+assumptions!$G$76)^2/12*(1+assumptions!$G$70+assumptions!$G$71+IF(32>=assumptions!$G$73,assumptions!$G$72,0))+assumptions!$G$74/12)+IF(32=E6,D6*assumptions!$G$75,0),0) -> 8758.112 | AM6: =IF(AND(33>=E6,OR(F6="",33<=F6)),(D6*(1+assumptions!$G$76)^2/12*(1+assumptions!$G$70+assumptions!$G$71+IF(33>=assumptions!$G$73,assumptions!$G$72,0))+assumptions!$G$74/12)+IF(33=E6,D6*assumptions!$G$75,0),0) -> 8758.112 | AN6: =IF(AND(34>=E6,OR(F6="",34<=F6)),(D6*(1+assumptions!$G$76)^2/12*(1+assumptions!$G$70+assumptions!$G$71+IF(34>=assumptions!$G$73,assumptions!$G$72,0))+assumptions!$G$74/12)+IF(34=E6,D6*assumptions!$G$75,0),0) -> 8758.112 | AO6: =IF(AND(35>=E6,OR(F6="",35<=F6)),(D6*(1+assumptions!$G$76)^2/12*(1+assumptions!$G$70+assumptions!$G$71+IF(35>=assumptions!$G$73,assumptions!$G$72,0))+assumptions!$G$74/12)+IF(35=E6,D6*assumptions!$G$75,0),0) -> 8758.112 | AP6: =IF(AND(36>=E6,OR(F6="",36<=F6)),(D6*(1+assumptions!$G$76)^2/12*(1+assumptions!$G$70+assumptions!$G$71+IF(36>=assumptions!$G$73,assumptions!$G$72,0))+assumptions!$G$74/12)+IF(36=E6,D6*assumptions!$G$75,0),0) -> 8758.112 | AQ6: =IF(AND(37>=E6,OR(F6="",37<=F6)),(D6*(1+assumptions!$G$76)^3/12*(1+assumptions!$G$70+assumptions!$G$71+IF(37>=assumptions!$G$73,assumptions!$G$72,0))+assumptions!$G$74/12)+IF(37=E6,D6*assumptions!$G$75,0),0) -> 9096.4365 | AR6: =IF(AND(38>=E6,OR(F6="",38<=F6)),(D6*(1+assumptions!$G$76)^3/12*(1+assumptions!$G$70+assumptions!$G$71+IF(38>=assumptions!$G$73,assumptions!$G$72,0))+assumptions!$G$74/12)+IF(38=E6,D6*assumptions!$G$75,0),0) -> 9096.4365 | AS6: =IF(AND(39>=E6,OR(F6="",39<=F6)),(D6*(1+assumptions!$G$76)^3/12*(1+assumptions!$G$70+assumptions!$G$71+IF(39>=assumptions!$G$73,assumptions!$G$72,0))+assumptions!$G$74/12)+IF(39=E6,D6*assumptions!$G$75,0),0) -> 9096.4365 | AT6: =IF(AND(40>=E6,OR(F6="",40<=F6)),(D6*(1+assumptions!$G$76)^3/12*(1+assumptions!$G$70+assumptions!$G$71+IF(40>=assumptions!$G$73,assumptions!$G$72,0))+assumptions!$G$74/12)+IF(40=E6,D6*assumptions!$G$75,0),0) -> 9096.4365 | AU6: =IF(AND(41>=E6,OR(F6="",41<=F6)),(D6*(1+assumptions!$G$76)^3/12*(1+assumptions!$G$70+assumptions!$G$71+IF(41>=assumptions!$G$73,assumptions!$G$72,0))+assumptions!$G$74/12)+IF(41=E6,D6*assumptions!$G$75,0),0) -> 9096.4365 | AV6: =IF(AND(42>=E6,OR(F6="",42<=F6)),(D6*(1+assumptions!$G$76)^3/12*(1+assumptions!$G$70+assumptions!$G$71+IF(42>=assumptions!$G$73,assumptions!$G$72,0))+assumptions!$G$74/12)+IF(42=E6,D6*assumptions!$G$75,0),0) -> 9096.4365 | AW6: =IF(AND(43>=E6,OR(F6="",43<=F6)),(D6*(1+assumptions!$G$76)^3/12*(1+assumptions!$G$70+assumptions!$G$71+IF(43>=assumptions!$G$73,assumptions!$G$72,0))+assumptions!$G$74/12)+IF(43=E6,D6*assumptions!$G$75,0),0) -> 9096.4365 | AX6: =IF(AND(44>=E6,OR(F6="",44<=F6)),(D6*(1+assumptions!$G$76)^3/12*(1+assumptions!$G$70+assumptions!$G$71+IF(44>=assumptions!$G$73,assumptions!$G$72,0))+assumptions!$G$74/12)+IF(44=E6,D6*assumptions!$G$75,0),0) -> 9096.4365 | AY6: =IF(AND(45>=E6,OR(F6="",45<=F6)),(D6*(1+assumptions!$G$76)^3/12*(1+assumptions!$G$70+assumptions!$G$71+IF(45>=assumptions!$G$73,assumptions!$G$72,0))+assumptions!$G$74/12)+IF(45=E6,D6*assumptions!$G$75,0),0) -> 9096.4365 | AZ6: =IF(AND(46>=E6,OR(F6="",46<=F6)),(D6*(1+assumptions!$G$76)^3/12*(1+assumptions!$G$70+assumptions!$G$71+IF(46>=assumptions!$G$73,assumptions!$G$72,0))+assumptions!$G$74/12)+IF(46=E6,D6*assumptions!$G$75,0),0) -> 9096.4365 | BA6: =IF(AND(47>=E6,OR(F6="",47<=F6)),(D6*(1+assumptions!$G$76)^3/12*(1+assumptions!$G$70+assumptions!$G$71+IF(47>=assumptions!$G$73,assumptions!$G$72,0))+assumptions!$G$74/12)+IF(47=E6,D6*assumptions!$G$75,0),0) -> 9096.4365 | BB6: =IF(AND(48>=E6,OR(F6="",48<=F6)),(D6*(1+assumptions!$G$76)^3/12*(1+assumptions!$G$70+assumptions!$G$71+IF(48>=assumptions!$G$73,assumptions!$G$72,0))+assumptions!$G$74/12)+IF(48=E6,D6*assumptions!$G$75,0),0) -> 9096.4365 | BC6: =IF(AND(49>=E6,OR(F6="",49<=F6)),(D6*(1+assumptions!$G$76)^4/12*(1+assumptions!$G$70+assumptions!$G$71+IF(49>=assumptions!$G$73,assumptions!$G$72,0))+assumptions!$G$74/12)+IF(49=E6,D6*assumptions!$G$75,0),0) -> 9448.2939 | BD6: =IF(AND(50>=E6,OR(F6="",50<=F6)),(D6*(1+assumptions!$G$76)^4/12*(1+assumptions!$G$70+assumptions!$G$71+IF(50>=assumptions!$G$73,assumptions!$G$72,0))+assumptions!$G$74/12)+IF(50=E6,D6*assumptions!$G$75,0),0) -> 9448.2939 | BE6: =IF(AND(51>=E6,OR(F6="",51<=F6)),(D6*(1+assumptions!$G$76)^4/12*(1+assumptions!$G$70+assumptions!$G$71+IF(51>=assumptions!$G$73,assumptions!$G$72,0))+assumptions!$G$74/12)+IF(51=E6,D6*assumptions!$G$75,0),0) -> 9448.2939 | BF6: =IF(AND(52>=E6,OR(F6="",52<=F6)),(D6*(1+assumptions!$G$76)^4/12*(1+assumptions!$G$70+assumptions!$G$71+IF(52>=assumptions!$G$73,assumptions!$G$72,0))+assumptions!$G$74/12)+IF(52=E6,D6*assumptions!$G$75,0),0) -> 9448.2939 | BG6: =IF(AND(53>=E6,OR(F6="",53<=F6)),(D6*(1+assumptions!$G$76)^4/12*(1+assumptions!$G$70+assumptions!$G$71+IF(53>=assumptions!$G$73,assumptions!$G$72,0))+assumptions!$G$74/12)+IF(53=E6,D6*assumptions!$G$75,0),0) -> 9448.2939 | BH6: =IF(AND(54>=E6,OR(F6="",54<=F6)),(D6*(1+assumptions!$G$76)^4/12*(1+assumptions!$G$70+assumptions!$G$71+IF(54>=assumptions!$G$73,assumptions!$G$72,0))+assumptions!$G$74/12)+IF(54=E6,D6*assumptions!$G$75,0),0) -> 9448.2939 | BI6: =IF(AND(55>=E6,OR(F6="",55<=F6)),(D6*(1+assumptions!$G$76)^4/12*(1+assumptions!$G$70+assumptions!$G$71+IF(55>=assumptions!$G$73,assumptions!$G$72,0))+assumptions!$G$74/12)+IF(55=E6,D6*assumptions!$G$75,0),0) -> 9448.2939 | BJ6: =IF(AND(56>=E6,OR(F6="",56<=F6)),(D6*(1+assumptions!$G$76)^4/12*(1+assumptions!$G$70+assumptions!$G$71+IF(56>=assumptions!$G$73,assumptions!$G$72,0))+assumptions!$G$74/12)+IF(56=E6,D6*assumptions!$G$75,0),0) -> 9448.2939 | BK6: =IF(AND(57>=E6,OR(F6="",57<=F6)),(D6*(1+assumptions!$G$76)^4/12*(1+assumptions!$G$70+assumptions!$G$71+IF(57>=assumptions!$G$73,assumptions!$G$72,0))+assumptions!$G$74/12)+IF(57=E6,D6*assumptions!$G$75,0),0) -> 9448.2939 | BL6: =IF(AND(58>=E6,OR(F6="",58<=F6)),(D6*(1+assumptions!$G$76)^4/12*(1+assumptions!$G$70+assumptions!$G$71+IF(58>=assumptions!$G$73,assumptions!$G$72,0))+assumptions!$G$74/12)+IF(58=E6,D6*assumptions!$G$75,0),0) -> 9448.2939 | BM6: =IF(AND(59>=E6,OR(F6="",59<=F6)),(D6*(1+assumptions!$G$76)^4/12*(1+assumptions!$G$70+assumptions!$G$71+IF(59>=assumptions!$G$73,assumptions!$G$72,0))+assumptions!$G$74/12)+IF(59=E6,D6*assumptions!$G$75,0),0) -> 9448.2939 | BN6: =IF(AND(60>=E6,OR(F6="",60<=F6)),(D6*(1+assumptions!$G$76)^4/12*(1+assumptions!$G$70+assumptions!$G$71+IF(60>=assumptions!$G$73,assumptions!$G$72,0))+assumptions!$G$74/12)+IF(60=E6,D6*assumptions!$G$75,0),0) -> 9448.2939
